<?xml version="1.0"?>
<robot name="centipede_7">

  <!-- Link definitions -->
  <!-- segment 0 -->
  <link name="seg_0">
    <visual>
      <geometry>
        <box size="0.3048 0.3048 0.1524"/>
      </geometry>
      <material name="silver">
        <color rgba="0.75 0.75 0.75 1"/>
      </material>
      <origin rpy="0 0 0" xyz="0 0 0"/>
    </visual>
    <collision>
      <geometry>
        <box size="0.3048 0.3048 0.1524"/>
      </geometry>
      <origin rpy="0 0 0" xyz="0 0 0"/>
    </collision>
    <inertial>
      <mass value="1.0"/>
      <inertia ixx="0.009677" iyy="0.01548" izz="0.009677"
               ixy="0.0" ixz="0.0" iyz="0.0"/>
      <origin rpy="0 0 0" xyz="0 0 0"/>
    </inertial>
  </link>

  <link name="seg_0_left_upper_leg_link">
    <visual>
      <geometry>
        <cylinder length="0.5" radius="0.0381"/>
      </geometry>
      <material name="silver">
        <color rgba="0.75 0.75 0.75 1"/>
      </material>
      <origin rpy="1.570796 0 0" xyz="0 0.25 0"/>
    </visual>
    <collision>
      <geometry>
        <cylinder length="0.5" radius="0.0381"/>
      </geometry>
      <origin rpy="1.570796 0 0" xyz="0 0.25 0"/>
    </collision>
    <inertial>
      <mass value="0.1"/>
      <inertia ixx="0.002120" iyy="0.002120" izz="0.00007258"
               ixy="0.0" ixz="0.0" iyz="0.0"/>
      <origin rpy="1.570796 0 0" xyz="0 0.25 0"/>
    </inertial>
  </link>

  <link name="seg_0_right_upper_leg_link">
    <visual>
      <geometry>
        <cylinder length="0.5" radius="0.0381"/>
      </geometry>
      <material name="silver">
        <color rgba="0.75 0.75 0.75 1"/>
      </material>
      <origin rpy="-1.570796 0 0" xyz="0 -0.25 0"/>
    </visual>
    <collision>
      <geometry>
        <cylinder length="0.5" radius="0.0381"/>
      </geometry>
      <origin rpy="-1.570796 0 0" xyz="0 -0.25 0"/>
    </collision>
    <inertial>
      <mass value="0.1"/>
      <inertia ixx="0.002120" iyy="0.002120" izz="0.00007258"
               ixy="0.0" ixz="0.0" iyz="0.0"/>
      <origin rpy="-1.570796 0 0" xyz="0 -0.25 0"/>
    </inertial>
  </link>

  <link name="seg_0_left_lower_leg_link">
    <visual>
      <geometry>
        <cylinder length="0.5" radius="0.0381"/>
      </geometry>
      <material name="silver">
        <color rgba="0.75 0.75 0.75 1"/>
      </material>
      <origin rpy="0 0 0" xyz="0 0 -0.25"/>
    </visual>
    <collision>
      <geometry>
        <cylinder length="0.5" radius="0.0381"/>
      </geometry>
      <origin rpy="0 0 0" xyz="0 0 -0.25"/>
    </collision>
    <inertial>
      <mass value="0.1"/>
      <inertia ixx="0.002120" iyy="0.002120" izz="0.00007258"
               ixy="0.0" ixz="0.0" iyz="0.0"/>
      <origin rpy="0 0 0" xyz="0 0 -0.25"/>
    </inertial>
  </link>

  <link name="seg_0_right_lower_leg_link">
    <visual>
      <geometry>
        <cylinder length="0.5" radius="0.0381"/>
      </geometry>
      <material name="silver">
        <color rgba="0.75 0.75 0.75 1"/>
      </material>
      <origin rpy="0 0 0" xyz="0 0 -0.25"/>
    </visual>
    <collision>
      <geometry>
        <cylinder length="0.5" radius="0.0381"/>
      </geometry>
      <origin rpy="0 0 0" xyz="0 0 -0.25"/>
    </collision>
    <inertial>
      <mass value="0.1"/>
      <inertia ixx="0.002120" iyy="0.002120" izz="0.00007258"
               ixy="0.0" ixz="0.0" iyz="0.0"/>
      <origin rpy="0 0 0" xyz="0 0 -0.25"/>
    </inertial>
  </link>

  <link name="seg_0_left_foot_link">
    <visual>
      <geometry>
        <cylinder length="0.05" radius="0.0381"/>
      </geometry>
      <material name="silver">
        <color rgba="0.75 0.75 0.75 1"/>
      </material>
      <origin rpy="0 0 0" xyz="0 0 -0.025"/>
    </visual>
    <collision>
      <geometry>
        <cylinder length="0.05" radius="0.0381"/>
      </geometry>
      <origin rpy="0 0 0" xyz="0 0 -0.025"/>
    </collision>
    <inertial>
      <mass value="0.1"/>
      <inertia ixx="0.00005712" iyy="0.00005712" izz="0.00007258"
               ixy="0.0" ixz="0.0" iyz="0.0"/>
      <origin rpy="0 0 0" xyz="0 0 -0.025"/>
    </inertial>
  </link>

  <link name="seg_0_right_foot_link">
    <visual>
      <geometry>
        <cylinder length="0.05" radius="0.0381"/>
      </geometry>
      <material name="silver">
        <color rgba="0.75 0.75 0.75 1"/>
      </material>
      <origin rpy="0 0 0" xyz="0 0 -0.025"/>
    </visual>
    <collision>
      <geometry>
        <cylinder length="0.05" radius="0.0381"/>
      </geometry>
      <origin rpy="0 0 0" xyz="0 0 -0.025"/>
    </collision>
    <inertial>
      <mass value="0.1"/>
      <inertia ixx="0.00005712" iyy="0.00005712" izz="0.00007258"
               ixy="0.0" ixz="0.0" iyz="0.0"/>
      <origin rpy="0 0 0" xyz="0 0 -0.025"/>
    </inertial>
  </link>

  <!-- segment 1 -->
  <link name="seg_1">
    <visual>
      <geometry>
        <box size="0.3048 0.3048 0.1524"/>
      </geometry>
      <material name="silver">
        <color rgba="0.75 0.75 0.75 1"/>
      </material>
      <origin rpy="0 0 0" xyz="0 0 0"/>
    </visual>
    <collision>
      <geometry>
        <box size="0.3048 0.3048 0.1524"/>
      </geometry>
      <origin rpy="0 0 0" xyz="0 0 0"/>
    </collision>
    <inertial>
      <mass value="1.0"/>
      <inertia ixx="0.009677" iyy="0.01548" izz="0.009677"
               ixy="0.0" ixz="0.0" iyz="0.0"/>
      <origin rpy="0 0 0" xyz="0 0 0"/>
    </inertial>
  </link>

  <link name="seg_1_left_upper_leg_link">
    <visual>
      <geometry>
        <cylinder length="0.5" radius="0.0381"/>
      </geometry>
      <material name="silver">
        <color rgba="0.75 0.75 0.75 1"/>
      </material>
      <origin rpy="1.570796 0 0" xyz="0 0.25 0"/>
    </visual>
    <collision>
      <geometry>
        <cylinder length="0.5" radius="0.0381"/>
      </geometry>
      <origin rpy="1.570796 0 0" xyz="0 0.25 0"/>
    </collision>
    <inertial>
      <mass value="0.1"/>
      <inertia ixx="0.002120" iyy="0.002120" izz="0.00007258"
               ixy="0.0" ixz="0.0" iyz="0.0"/>
      <origin rpy="1.570796 0 0" xyz="0 0.25 0"/>
    </inertial>
  </link>

  <link name="seg_1_right_upper_leg_link">
    <visual>
      <geometry>
        <cylinder length="0.5" radius="0.0381"/>
      </geometry>
      <material name="silver">
        <color rgba="0.75 0.75 0.75 1"/>
      </material>
      <origin rpy="-1.570796 0 0" xyz="0 -0.25 0"/>
    </visual>
    <collision>
      <geometry>
        <cylinder length="0.5" radius="0.0381"/>
      </geometry>
      <origin rpy="-1.570796 0 0" xyz="0 -0.25 0"/>
    </collision>
    <inertial>
      <mass value="0.1"/>
      <inertia ixx="0.002120" iyy="0.002120" izz="0.00007258"
               ixy="0.0" ixz="0.0" iyz="0.0"/>
      <origin rpy="-1.570796 0 0" xyz="0 -0.25 0"/>
    </inertial>
  </link>

  <link name="seg_1_left_lower_leg_link">
    <visual>
      <geometry>
        <cylinder length="0.5" radius="0.0381"/>
      </geometry>
      <material name="silver">
        <color rgba="0.75 0.75 0.75 1"/>
      </material>
      <origin rpy="0 0 0" xyz="0 0 -0.25"/>
    </visual>
    <collision>
      <geometry>
        <cylinder length="0.5" radius="0.0381"/>
      </geometry>
      <origin rpy="0 0 0" xyz="0 0 -0.25"/>
    </collision>
    <inertial>
      <mass value="0.1"/>
      <inertia ixx="0.002120" iyy="0.002120" izz="0.00007258"
               ixy="0.0" ixz="0.0" iyz="0.0"/>
      <origin rpy="0 0 0" xyz="0 0 -0.25"/>
    </inertial>
  </link>

  <link name="seg_1_right_lower_leg_link">
    <visual>
      <geometry>
        <cylinder length="0.5" radius="0.0381"/>
      </geometry>
      <material name="silver">
        <color rgba="0.75 0.75 0.75 1"/>
      </material>
      <origin rpy="0 0 0" xyz="0 0 -0.25"/>
    </visual>
    <collision>
      <geometry>
        <cylinder length="0.5" radius="0.0381"/>
      </geometry>
      <origin rpy="0 0 0" xyz="0 0 -0.25"/>
    </collision>
    <inertial>
      <mass value="0.1"/>
      <inertia ixx="0.002120" iyy="0.002120" izz="0.00007258"
               ixy="0.0" ixz="0.0" iyz="0.0"/>
      <origin rpy="0 0 0" xyz="0 0 -0.25"/>
    </inertial>
  </link>

  <link name="seg_1_left_foot_link">
    <visual>
      <geometry>
        <cylinder length="0.05" radius="0.0381"/>
      </geometry>
      <material name="silver">
        <color rgba="0.75 0.75 0.75 1"/>
      </material>
      <origin rpy="0 0 0" xyz="0 0 -0.025"/>
    </visual>
    <collision>
      <geometry>
        <cylinder length="0.05" radius="0.0381"/>
      </geometry>
      <origin rpy="0 0 0" xyz="0 0 -0.025"/>
    </collision>
    <inertial>
      <mass value="0.1"/>
      <inertia ixx="0.00005712" iyy="0.00005712" izz="0.00007258"
               ixy="0.0" ixz="0.0" iyz="0.0"/>
      <origin rpy="0 0 0" xyz="0 0 -0.025"/>
    </inertial>
  </link>

  <link name="seg_1_right_foot_link">
    <visual>
      <geometry>
        <cylinder length="0.05" radius="0.0381"/>
      </geometry>
      <material name="silver">
        <color rgba="0.75 0.75 0.75 1"/>
      </material>
      <origin rpy="0 0 0" xyz="0 0 -0.025"/>
    </visual>
    <collision>
      <geometry>
        <cylinder length="0.05" radius="0.0381"/>
      </geometry>
      <origin rpy="0 0 0" xyz="0 0 -0.025"/>
    </collision>
    <inertial>
      <mass value="0.1"/>
      <inertia ixx="0.00005712" iyy="0.00005712" izz="0.00007258"
               ixy="0.0" ixz="0.0" iyz="0.0"/>
      <origin rpy="0 0 0" xyz="0 0 -0.025"/>
    </inertial>
  </link>

  <!-- segment 2 -->
  <link name="seg_2">
    <visual>
      <geometry>
        <box size="0.3048 0.3048 0.1524"/>
      </geometry>
      <material name="silver">
        <color rgba="0.75 0.75 0.75 1"/>
      </material>
      <origin rpy="0 0 0" xyz="0 0 0"/>
    </visual>
    <collision>
      <geometry>
        <box size="0.3048 0.3048 0.1524"/>
      </geometry>
      <origin rpy="0 0 0" xyz="0 0 0"/>
    </collision>
    <inertial>
      <mass value="1.0"/>
      <inertia ixx="0.009677" iyy="0.01548" izz="0.009677"
               ixy="0.0" ixz="0.0" iyz="0.0"/>
      <origin rpy="0 0 0" xyz="0 0 0"/>
    </inertial>
  </link>

  <link name="seg_2_left_upper_leg_link">
    <visual>
      <geometry>
        <cylinder length="0.5" radius="0.0381"/>
      </geometry>
      <material name="silver">
        <color rgba="0.75 0.75 0.75 1"/>
      </material>
      <origin rpy="1.570796 0 0" xyz="0 0.25 0"/>
    </visual>
    <collision>
      <geometry>
        <cylinder length="0.5" radius="0.0381"/>
      </geometry>
      <origin rpy="1.570796 0 0" xyz="0 0.25 0"/>
    </collision>
    <inertial>
      <mass value="0.1"/>
      <inertia ixx="0.002120" iyy="0.002120" izz="0.00007258"
               ixy="0.0" ixz="0.0" iyz="0.0"/>
      <origin rpy="1.570796 0 0" xyz="0 0.25 0"/>
    </inertial>
  </link>

  <link name="seg_2_right_upper_leg_link">
    <visual>
      <geometry>
        <cylinder length="0.5" radius="0.0381"/>
      </geometry>
      <material name="silver">
        <color rgba="0.75 0.75 0.75 1"/>
      </material>
      <origin rpy="-1.570796 0 0" xyz="0 -0.25 0"/>
    </visual>
    <collision>
      <geometry>
        <cylinder length="0.5" radius="0.0381"/>
      </geometry>
      <origin rpy="-1.570796 0 0" xyz="0 -0.25 0"/>
    </collision>
    <inertial>
      <mass value="0.1"/>
      <inertia ixx="0.002120" iyy="0.002120" izz="0.00007258"
               ixy="0.0" ixz="0.0" iyz="0.0"/>
      <origin rpy="-1.570796 0 0" xyz="0 -0.25 0"/>
    </inertial>
  </link>

  <link name="seg_2_left_lower_leg_link">
    <visual>
      <geometry>
        <cylinder length="0.5" radius="0.0381"/>
      </geometry>
      <material name="silver">
        <color rgba="0.75 0.75 0.75 1"/>
      </material>
      <origin rpy="0 0 0" xyz="0 0 -0.25"/>
    </visual>
    <collision>
      <geometry>
        <cylinder length="0.5" radius="0.0381"/>
      </geometry>
      <origin rpy="0 0 0" xyz="0 0 -0.25"/>
    </collision>
    <inertial>
      <mass value="0.1"/>
      <inertia ixx="0.002120" iyy="0.002120" izz="0.00007258"
               ixy="0.0" ixz="0.0" iyz="0.0"/>
      <origin rpy="0 0 0" xyz="0 0 -0.25"/>
    </inertial>
  </link>

  <link name="seg_2_right_lower_leg_link">
    <visual>
      <geometry>
        <cylinder length="0.5" radius="0.0381"/>
      </geometry>
      <material name="silver">
        <color rgba="0.75 0.75 0.75 1"/>
      </material>
      <origin rpy="0 0 0" xyz="0 0 -0.25"/>
    </visual>
    <collision>
      <geometry>
        <cylinder length="0.5" radius="0.0381"/>
      </geometry>
      <origin rpy="0 0 0" xyz="0 0 -0.25"/>
    </collision>
    <inertial>
      <mass value="0.1"/>
      <inertia ixx="0.002120" iyy="0.002120" izz="0.00007258"
               ixy="0.0" ixz="0.0" iyz="0.0"/>
      <origin rpy="0 0 0" xyz="0 0 -0.25"/>
    </inertial>
  </link>

  <link name="seg_2_left_foot_link">
    <visual>
      <geometry>
        <cylinder length="0.05" radius="0.0381"/>
      </geometry>
      <material name="silver">
        <color rgba="0.75 0.75 0.75 1"/>
      </material>
      <origin rpy="0 0 0" xyz="0 0 -0.025"/>
    </visual>
    <collision>
      <geometry>
        <cylinder length="0.05" radius="0.0381"/>
      </geometry>
      <origin rpy="0 0 0" xyz="0 0 -0.025"/>
    </collision>
    <inertial>
      <mass value="0.1"/>
      <inertia ixx="0.00005712" iyy="0.00005712" izz="0.00007258"
               ixy="0.0" ixz="0.0" iyz="0.0"/>
      <origin rpy="0 0 0" xyz="0 0 -0.025"/>
    </inertial>
  </link>

  <link name="seg_2_right_foot_link">
    <visual>
      <geometry>
        <cylinder length="0.05" radius="0.0381"/>
      </geometry>
      <material name="silver">
        <color rgba="0.75 0.75 0.75 1"/>
      </material>
      <origin rpy="0 0 0" xyz="0 0 -0.025"/>
    </visual>
    <collision>
      <geometry>
        <cylinder length="0.05" radius="0.0381"/>
      </geometry>
      <origin rpy="0 0 0" xyz="0 0 -0.025"/>
    </collision>
    <inertial>
      <mass value="0.1"/>
      <inertia ixx="0.00005712" iyy="0.00005712" izz="0.00007258"
               ixy="0.0" ixz="0.0" iyz="0.0"/>
      <origin rpy="0 0 0" xyz="0 0 -0.025"/>
    </inertial>
  </link>

  <!-- segment 3 -->
  <link name="seg_3">
    <visual>
      <geometry>
        <box size="0.3048 0.3048 0.1524"/>
      </geometry>
      <material name="silver">
        <color rgba="0.75 0.75 0.75 1"/>
      </material>
      <origin rpy="0 0 0" xyz="0 0 0"/>
    </visual>
    <collision>
      <geometry>
        <box size="0.3048 0.3048 0.1524"/>
      </geometry>
      <origin rpy="0 0 0" xyz="0 0 0"/>
    </collision>
    <inertial>
      <mass value="1.0"/>
      <inertia ixx="0.009677" iyy="0.01548" izz="0.009677"
               ixy="0.0" ixz="0.0" iyz="0.0"/>
      <origin rpy="0 0 0" xyz="0 0 0"/>
    </inertial>
  </link>

  <link name="seg_3_left_upper_leg_link">
    <visual>
      <geometry>
        <cylinder length="0.5" radius="0.0381"/>
      </geometry>
      <material name="silver">
        <color rgba="0.75 0.75 0.75 1"/>
      </material>
      <origin rpy="1.570796 0 0" xyz="0 0.25 0"/>
    </visual>
    <collision>
      <geometry>
        <cylinder length="0.5" radius="0.0381"/>
      </geometry>
      <origin rpy="1.570796 0 0" xyz="0 0.25 0"/>
    </collision>
    <inertial>
      <mass value="0.1"/>
      <inertia ixx="0.002120" iyy="0.002120" izz="0.00007258"
               ixy="0.0" ixz="0.0" iyz="0.0"/>
      <origin rpy="1.570796 0 0" xyz="0 0.25 0"/>
    </inertial>
  </link>

  <link name="seg_3_right_upper_leg_link">
    <visual>
      <geometry>
        <cylinder length="0.5" radius="0.0381"/>
      </geometry>
      <material name="silver">
        <color rgba="0.75 0.75 0.75 1"/>
      </material>
      <origin rpy="-1.570796 0 0" xyz="0 -0.25 0"/>
    </visual>
    <collision>
      <geometry>
        <cylinder length="0.5" radius="0.0381"/>
      </geometry>
      <origin rpy="-1.570796 0 0" xyz="0 -0.25 0"/>
    </collision>
    <inertial>
      <mass value="0.1"/>
      <inertia ixx="0.002120" iyy="0.002120" izz="0.00007258"
               ixy="0.0" ixz="0.0" iyz="0.0"/>
      <origin rpy="-1.570796 0 0" xyz="0 -0.25 0"/>
    </inertial>
  </link>

  <link name="seg_3_left_lower_leg_link">
    <visual>
      <geometry>
        <cylinder length="0.5" radius="0.0381"/>
      </geometry>
      <material name="silver">
        <color rgba="0.75 0.75 0.75 1"/>
      </material>
      <origin rpy="0 0 0" xyz="0 0 -0.25"/>
    </visual>
    <collision>
      <geometry>
        <cylinder length="0.5" radius="0.0381"/>
      </geometry>
      <origin rpy="0 0 0" xyz="0 0 -0.25"/>
    </collision>
    <inertial>
      <mass value="0.1"/>
      <inertia ixx="0.002120" iyy="0.002120" izz="0.00007258"
               ixy="0.0" ixz="0.0" iyz="0.0"/>
      <origin rpy="0 0 0" xyz="0 0 -0.25"/>
    </inertial>
  </link>

  <link name="seg_3_right_lower_leg_link">
    <visual>
      <geometry>
        <cylinder length="0.5" radius="0.0381"/>
      </geometry>
      <material name="silver">
        <color rgba="0.75 0.75 0.75 1"/>
      </material>
      <origin rpy="0 0 0" xyz="0 0 -0.25"/>
    </visual>
    <collision>
      <geometry>
        <cylinder length="0.5" radius="0.0381"/>
      </geometry>
      <origin rpy="0 0 0" xyz="0 0 -0.25"/>
    </collision>
    <inertial>
      <mass value="0.1"/>
      <inertia ixx="0.002120" iyy="0.002120" izz="0.00007258"
               ixy="0.0" ixz="0.0" iyz="0.0"/>
      <origin rpy="0 0 0" xyz="0 0 -0.25"/>
    </inertial>
  </link>

  <link name="seg_3_left_foot_link">
    <visual>
      <geometry>
        <cylinder length="0.05" radius="0.0381"/>
      </geometry>
      <material name="silver">
        <color rgba="0.75 0.75 0.75 1"/>
      </material>
      <origin rpy="0 0 0" xyz="0 0 -0.025"/>
    </visual>
    <collision>
      <geometry>
        <cylinder length="0.05" radius="0.0381"/>
      </geometry>
      <origin rpy="0 0 0" xyz="0 0 -0.025"/>
    </collision>
    <inertial>
      <mass value="0.1"/>
      <inertia ixx="0.00005712" iyy="0.00005712" izz="0.00007258"
               ixy="0.0" ixz="0.0" iyz="0.0"/>
      <origin rpy="0 0 0" xyz="0 0 -0.025"/>
    </inertial>
  </link>

  <link name="seg_3_right_foot_link">
    <visual>
      <geometry>
        <cylinder length="0.05" radius="0.0381"/>
      </geometry>
      <material name="silver">
        <color rgba="0.75 0.75 0.75 1"/>
      </material>
      <origin rpy="0 0 0" xyz="0 0 -0.025"/>
    </visual>
    <collision>
      <geometry>
        <cylinder length="0.05" radius="0.0381"/>
      </geometry>
      <origin rpy="0 0 0" xyz="0 0 -0.025"/>
    </collision>
    <inertial>
      <mass value="0.1"/>
      <inertia ixx="0.00005712" iyy="0.00005712" izz="0.00007258"
               ixy="0.0" ixz="0.0" iyz="0.0"/>
      <origin rpy="0 0 0" xyz="0 0 -0.025"/>
    </inertial>
  </link>

  <!-- segment 4 -->
  <link name="seg_4">
    <visual>
      <geometry>
        <box size="0.3048 0.3048 0.1524"/>
      </geometry>
      <material name="silver">
        <color rgba="0.75 0.75 0.75 1"/>
      </material>
      <origin rpy="0 0 0" xyz="0 0 0"/>
    </visual>
    <collision>
      <geometry>
        <box size="0.3048 0.3048 0.1524"/>
      </geometry>
      <origin rpy="0 0 0" xyz="0 0 0"/>
    </collision>
    <inertial>
      <mass value="1.0"/>
      <inertia ixx="0.009677" iyy="0.01548" izz="0.009677"
               ixy="0.0" ixz="0.0" iyz="0.0"/>
      <origin rpy="0 0 0" xyz="0 0 0"/>
    </inertial>
  </link>

  <link name="seg_4_left_upper_leg_link">
    <visual>
      <geometry>
        <cylinder length="0.5" radius="0.0381"/>
      </geometry>
      <material name="silver">
        <color rgba="0.75 0.75 0.75 1"/>
      </material>
      <origin rpy="1.570796 0 0" xyz="0 0.25 0"/>
    </visual>
    <collision>
      <geometry>
        <cylinder length="0.5" radius="0.0381"/>
      </geometry>
      <origin rpy="1.570796 0 0" xyz="0 0.25 0"/>
    </collision>
    <inertial>
      <mass value="0.1"/>
      <inertia ixx="0.002120" iyy="0.002120" izz="0.00007258"
               ixy="0.0" ixz="0.0" iyz="0.0"/>
      <origin rpy="1.570796 0 0" xyz="0 0.25 0"/>
    </inertial>
  </link>

  <link name="seg_4_right_upper_leg_link">
    <visual>
      <geometry>
        <cylinder length="0.5" radius="0.0381"/>
      </geometry>
      <material name="silver">
        <color rgba="0.75 0.75 0.75 1"/>
      </material>
      <origin rpy="-1.570796 0 0" xyz="0 -0.25 0"/>
    </visual>
    <collision>
      <geometry>
        <cylinder length="0.5" radius="0.0381"/>
      </geometry>
      <origin rpy="-1.570796 0 0" xyz="0 -0.25 0"/>
    </collision>
    <inertial>
      <mass value="0.1"/>
      <inertia ixx="0.002120" iyy="0.002120" izz="0.00007258"
               ixy="0.0" ixz="0.0" iyz="0.0"/>
      <origin rpy="-1.570796 0 0" xyz="0 -0.25 0"/>
    </inertial>
  </link>

  <link name="seg_4_left_lower_leg_link">
    <visual>
      <geometry>
        <cylinder length="0.5" radius="0.0381"/>
      </geometry>
      <material name="silver">
        <color rgba="0.75 0.75 0.75 1"/>
      </material>
      <origin rpy="0 0 0" xyz="0 0 -0.25"/>
    </visual>
    <collision>
      <geometry>
        <cylinder length="0.5" radius="0.0381"/>
      </geometry>
      <origin rpy="0 0 0" xyz="0 0 -0.25"/>
    </collision>
    <inertial>
      <mass value="0.1"/>
      <inertia ixx="0.002120" iyy="0.002120" izz="0.00007258"
               ixy="0.0" ixz="0.0" iyz="0.0"/>
      <origin rpy="0 0 0" xyz="0 0 -0.25"/>
    </inertial>
  </link>

  <link name="seg_4_right_lower_leg_link">
    <visual>
      <geometry>
        <cylinder length="0.5" radius="0.0381"/>
      </geometry>
      <material name="silver">
        <color rgba="0.75 0.75 0.75 1"/>
      </material>
      <origin rpy="0 0 0" xyz="0 0 -0.25"/>
    </visual>
    <collision>
      <geometry>
        <cylinder length="0.5" radius="0.0381"/>
      </geometry>
      <origin rpy="0 0 0" xyz="0 0 -0.25"/>
    </collision>
    <inertial>
      <mass value="0.1"/>
      <inertia ixx="0.002120" iyy="0.002120" izz="0.00007258"
               ixy="0.0" ixz="0.0" iyz="0.0"/>
      <origin rpy="0 0 0" xyz="0 0 -0.25"/>
    </inertial>
  </link>

  <link name="seg_4_left_foot_link">
    <visual>
      <geometry>
        <cylinder length="0.05" radius="0.0381"/>
      </geometry>
      <material name="silver">
        <color rgba="0.75 0.75 0.75 1"/>
      </material>
      <origin rpy="0 0 0" xyz="0 0 -0.025"/>
    </visual>
    <collision>
      <geometry>
        <cylinder length="0.05" radius="0.0381"/>
      </geometry>
      <origin rpy="0 0 0" xyz="0 0 -0.025"/>
    </collision>
    <inertial>
      <mass value="0.1"/>
      <inertia ixx="0.00005712" iyy="0.00005712" izz="0.00007258"
               ixy="0.0" ixz="0.0" iyz="0.0"/>
      <origin rpy="0 0 0" xyz="0 0 -0.025"/>
    </inertial>
  </link>

  <link name="seg_4_right_foot_link">
    <visual>
      <geometry>
        <cylinder length="0.05" radius="0.0381"/>
      </geometry>
      <material name="silver">
        <color rgba="0.75 0.75 0.75 1"/>
      </material>
      <origin rpy="0 0 0" xyz="0 0 -0.025"/>
    </visual>
    <collision>
      <geometry>
        <cylinder length="0.05" radius="0.0381"/>
      </geometry>
      <origin rpy="0 0 0" xyz="0 0 -0.025"/>
    </collision>
    <inertial>
      <mass value="0.1"/>
      <inertia ixx="0.00005712" iyy="0.00005712" izz="0.00007258"
               ixy="0.0" ixz="0.0" iyz="0.0"/>
      <origin rpy="0 0 0" xyz="0 0 -0.025"/>
    </inertial>
  </link>

  <!-- segment 5 -->
  <link name="seg_5">
    <visual>
      <geometry>
        <box size="0.3048 0.3048 0.1524"/>
      </geometry>
      <material name="silver">
        <color rgba="0.75 0.75 0.75 1"/>
      </material>
      <origin rpy="0 0 0" xyz="0 0 0"/>
    </visual>
    <collision>
      <geometry>
        <box size="0.3048 0.3048 0.1524"/>
      </geometry>
      <origin rpy="0 0 0" xyz="0 0 0"/>
    </collision>
    <inertial>
      <mass value="1.0"/>
      <inertia ixx="0.009677" iyy="0.01548" izz="0.009677"
               ixy="0.0" ixz="0.0" iyz="0.0"/>
      <origin rpy="0 0 0" xyz="0 0 0"/>
    </inertial>
  </link>

  <link name="seg_5_left_upper_leg_link">
    <visual>
      <geometry>0
        <cylinder length="0.5" radius="0.0381"/>
      </geometry>
      <material name="silver">
        <color rgba="0.75 0.75 0.75 1"/>
      </material>
      <origin rpy="1.570796 0 0" xyz="0 0.25 0"/>
    </visual>
    <collision>
      <geometry>
        <cylinder length="0.5" radius="0.0381"/>
      </geometry>
      <origin rpy="1.570796 0 0" xyz="0 0.25 0"/>
    </collision>
    <inertial>
      <mass value="0.1"/>
      <inertia ixx="0.002120" iyy="0.002120" izz="0.00007258"
               ixy="0.0" ixz="0.0" iyz="0.0"/>
      <origin rpy="1.570796 0 0" xyz="0 0.25 0"/>
    </inertial>
  </link>

  <link name="seg_5_right_upper_leg_link">
    <visual>
      <geometry>
        <cylinder length="0.5" radius="0.0381"/>
      </geometry>
      <material name="silver">
        <color rgba="0.75 0.75 0.75 1"/>
      </material>
      <origin rpy="-1.570796 0 0" xyz="0 -0.25 0"/>
    </visual>
    <collision>
      <geometry>
        <cylinder length="0.5" radius="0.0381"/>
      </geometry>
      <origin rpy="-1.570796 0 0" xyz="0 -0.25 0"/>
    </collision>
    <inertial>
      <mass value="0.1"/>
      <inertia ixx="0.002120" iyy="0.002120" izz="0.00007258"
               ixy="0.0" ixz="0.0" iyz="0.0"/>
      <origin rpy="-1.570796 0 0" xyz="0 -0.25 0"/>
    </inertial>
  </link>

  <link name="seg_5_left_lower_leg_link">
    <visual>
      <geometry>
        <cylinder length="0.5" radius="0.0381"/>
      </geometry>
      <material name="silver">
        <color rgba="0.75 0.75 0.75 1"/>
      </material>
      <origin rpy="0 0 0" xyz="0 0 -0.25"/>
    </visual>
    <collision>
      <geometry>
        <cylinder length="0.5" radius="0.0381"/>
      </geometry>
      <origin rpy="0 0 0" xyz="0 0 -0.25"/>
    </collision>
    <inertial>
      <mass value="0.1"/>
      <inertia ixx="0.002120" iyy="0.002120" izz="0.00007258"
               ixy="0.0" ixz="0.0" iyz="0.0"/>
      <origin rpy="0 0 0" xyz="0 0 -0.25"/>
    </inertial>
  </link>

  <link name="seg_5_right_lower_leg_link">
    <visual>
      <geometry>
        <cylinder length="0.5" radius="0.0381"/>
      </geometry>
      <material name="silver">
        <color rgba="0.75 0.75 0.75 1"/>
      </material>
      <origin rpy="0 0 0" xyz="0 0 -0.25"/>
    </visual>
    <collision>
      <geometry>
        <cylinder length="0.5" radius="0.0381"/>
      </geometry>
      <origin rpy="0 0 0" xyz="0 0 -0.25"/>
    </collision>
    <inertial>
      <mass value="0.1"/>
      <inertia ixx="0.002120" iyy="0.002120" izz="0.00007258"
               ixy="0.0" ixz="0.0" iyz="0.0"/>
      <origin rpy="0 0 0" xyz="0 0 -0.25"/>
    </inertial>
  </link>

  <link name="seg_5_left_foot_link">
    <visual>
      <geometry>
        <cylinder length="0.05" radius="0.0381"/>
      </geometry>
      <material name="silver">
        <color rgba="0.75 0.75 0.75 1"/>
      </material>
      <origin rpy="0 0 0" xyz="0 0 -0.025"/>
    </visual>
    <collision>
      <geometry>
        <cylinder length="0.05" radius="0.0381"/>
      </geometry>
      <origin rpy="0 0 0" xyz="0 0 -0.025"/>
    </collision>
    <inertial>
      <mass value="0.1"/>
      <inertia ixx="0.00005712" iyy="0.00005712" izz="0.00007258"
               ixy="0.0" ixz="0.0" iyz="0.0"/>
      <origin rpy="0 0 0" xyz="0 0 -0.025"/>
    </inertial>
  </link>

  <link name="seg_5_right_foot_link">
    <visual>
      <geometry>
        <cylinder length="0.05" radius="0.0381"/>
      </geometry>
      <material name="silver">
        <color rgba="0.75 0.75 0.75 1"/>
      </material>
      <origin rpy="0 0 0" xyz="0 0 -0.025"/>
    </visual>
    <collision>
      <geometry>
        <cylinder length="0.05" radius="0.0381"/>
      </geometry>
      <origin rpy="0 0 0" xyz="0 0 -0.025"/>
    </collision>
    <inertial>
      <mass value="0.1"/>
      <inertia ixx="0.00005712" iyy="0.00005712" izz="0.00007258"
               ixy="0.0" ixz="0.0" iyz="0.0"/>
      <origin rpy="0 0 0" xyz="0 0 -0.025"/>
    </inertial>
  </link>

  <!-- segment connectors -->
  <link name="connector_0">
    <visual>
      <geometry>
        <cylinder length="0.4572" radius="0.0381"/>
      </geometry>
      <material name="silver">
        <color rgba="0.75 0.75 0.75 1"/>
      </material>
      <origin rpy="0 1.57079633 0" xyz="-0.2286 0 0"/>
    </visual>
    <collision>
      <geometry>
        <cylinder length="0.4572" radius="0.0381"/>
      </geometry>
      <origin rpy="0 1.57079633 0" xyz="-0.2286 0 0"/>
    </collision>
    <inertial>
      <mass value="0.1"/>
      <inertia ixx="0.0008105" iyy="0.0008105" izz="0.00007258"
               ixy="0.0" ixz="0.0" iyz="0.0"/>
      <origin rpy="0 1.57079633 0" xyz="-0.2286 0 0"/>
    </inertial>
  </link>

  <link name="connector_0_b">
    <visual>
      <geometry>
        <box size="0.1 0.1 0.1"/>
      </geometry>
      <material name="silver">
        <color rgba="0.75 0.75 0.75 1"/>
      </material>
      <origin rpy="0 0 0" xyz="0 0 0"/>
    </visual>
    <collision>
      <geometry>
        <box size="0.1 0.1 0.1"/>
      </geometry>
      <origin rpy="0 0 0" xyz="0 0 0"/>
    </collision>
    <inertial>
      <mass value="0.1"/>
      <inertia ixx="0.0001667" iyy="0.0001667" izz="0.0001667"
               ixy="0.0" ixz="0.0" iyz="0.0"/>
      <origin rpy="0 0 0" xyz="0 0 0"/>
    </inertial>
  </link>

  <link name="connector_1">
    <visual>
      <geometry>
        <cylinder length="0.4572" radius="0.0381"/>
      </geometry>
      <material name="silver">
        <color rgba="0.75 0.75 0.75 1"/>
      </material>
      <origin rpy="0 1.57079633 0" xyz="-0.2286 0 0"/>
    </visual>
    <collision>
      <geometry>
        <cylinder length="0.4572" radius="0.0381"/>
      </geometry>
      <origin rpy="0 1.57079633 0" xyz="-0.2286 0 0"/>
    </collision>
    <inertial>
      <mass value="0.1"/>
      <inertia ixx="0.0008105" iyy="0.0008105" izz="0.00007258"
               ixy="0.0" ixz="0.0" iyz="0.0"/>
      <origin rpy="0 1.57079633 0" xyz="-0.2286 0 0"/>
    </inertial>
  </link>

  <link name="connector_1_b">
    <visual>
      <geometry>
        <box size="0.1 0.1 0.1"/>
      </geometry>
      <material name="silver">
        <color rgba="0.75 0.75 0.75 1"/>
      </material>
      <origin rpy="0 0 0" xyz="0 0 0"/>
    </visual>
    <collision>
      <geometry>
        <box size="0.1 0.1 0.1"/>
      </geometry>
      <origin rpy="0 0 0" xyz="0 0 0"/>
    </collision>
    <inertial>
      <mass value="0.1"/>
      <inertia ixx="0.0001667" iyy="0.0001667" izz="0.0001667"
               ixy="0.0" ixz="0.0" iyz="0.0"/>
      <origin rpy="0 0 0" xyz="0 0 0"/>
    </inertial>
  </link>

  <link name="connector_2">
    <visual>
      <geometry>
        <cylinder length="0.4572" radius="0.0381"/>
      </geometry>
      <material name="silver">
        <color rgba="0.75 0.75 0.75 1"/>
      </material>
      <origin rpy="0 1.57079633 0" xyz="-0.2286 0 0"/>
    </visual>
    <collision>
      <geometry>
        <cylinder length="0.4572" radius="0.0381"/>
      </geometry>
      <origin rpy="0 1.57079633 0" xyz="-0.2286 0 0"/>
    </collision>
    <inertial>
      <mass value="0.1"/>
      <inertia ixx="0.0008105" iyy="0.0008105" izz="0.00007258"
               ixy="0.0" ixz="0.0" iyz="0.0"/>
      <origin rpy="0 1.57079633 0" xyz="-0.2286 0 0"/>
    </inertial>
  </link>

  <link name="connector_2_b">
    <visual>
      <geometry>
        <box size="0.1 0.1 0.1"/>
      </geometry>
      <material name="silver">
        <color rgba="0.75 0.75 0.75 1"/>
      </material>
      <origin rpy="0 0 0" xyz="0 0 0"/>
    </visual>
    <collision>
      <geometry>
        <box size="0.1 0.1 0.1"/>
      </geometry>
      <origin rpy="0 0 0" xyz="0 0 0"/>
    </collision>
    <inertial>
      <mass value="0.1"/>
      <inertia ixx="0.0001667" iyy="0.0001667" izz="0.0001667"
               ixy="0.0" ixz="0.0" iyz="0.0"/>
      <origin rpy="0 0 0" xyz="0 0 0"/>
    </inertial>
  </link>

  <link name="connector_3">
    <visual>
      <geometry>
        <cylinder length="0.4572" radius="0.0381"/>
      </geometry>
      <material name="silver">
        <color rgba="0.75 0.75 0.75 1"/>
      </material>
      <origin rpy="0 1.57079633 0" xyz="-0.2286 0 0"/>
    </visual>
    <collision>
      <geometry>
        <cylinder length="0.4572" radius="0.0381"/>
      </geometry>
      <origin rpy="0 1.57079633 0" xyz="-0.2286 0 0"/>
    </collision>
    <inertial>
      <mass value="0.1"/>
      <inertia ixx="0.0008105" iyy="0.0008105" izz="0.00007258"
               ixy="0.0" ixz="0.0" iyz="0.0"/>
      <origin rpy="0 1.57079633 0" xyz="-0.2286 0 0"/>
    </inertial>
  </link>

  <link name="connector_3_b">
    <visual>
      <geometry>
        <box size="0.1 0.1 0.1"/>
      </geometry>
      <material name="silver">
        <color rgba="0.75 0.75 0.75 1"/>
      </material>
      <origin rpy="0 0 0" xyz="0 0 0"/>
    </visual>
    <collision>
      <geometry>
        <box size="0.1 0.1 0.1"/>
      </geometry>
      <origin rpy="0 0 0" xyz="0 0 0"/>
    </collision>
    <inertial>
      <mass value="0.1"/>
      <inertia ixx="0.0001667" iyy="0.0001667" izz="0.0001667"
               ixy="0.0" ixz="0.0" iyz="0.0"/>
      <origin rpy="0 0 0" xyz="0 0 0"/>
    </inertial>
  </link>

  <link name="connector_4">
    <visual>
      <geometry>
        <cylinder length="0.4572" radius="0.0381"/>
      </geometry>
      <material name="silver">
        <color rgba="0.75 0.75 0.75 1"/>
      </material>
      <origin rpy="0 1.57079633 0" xyz="-0.2286 0 0"/>
    </visual>
    <collision>
      <geometry>
        <cylinder length="0.4572" radius="0.0381"/>
      </geometry>
      <origin rpy="0 1.57079633 0" xyz="-0.2286 0 0"/>
    </collision>
    <inertial>
      <mass value="0.1"/>
      <inertia ixx="0.0008105" iyy="0.0008105" izz="0.00007258"
               ixy="0.0" ixz="0.0" iyz="0.0"/>
      <origin rpy="0 1.57079633 0" xyz="-0.2286 0 0"/>
    </inertial>
  </link>

  <link name="connector_4_b">
    <visual>
      <geometry>
        <box size="0.1 0.1 0.1"/>
      </geometry>
      <material name="silver">
        <color rgba="0.75 0.75 0.75 1"/>
      </material>
      <origin rpy="0 0 0" xyz="0 0 0"/>
    </visual>
    <collision>
      <geometry>
        <box size="0.1 0.1 0.1"/>
      </geometry>
      <origin rpy="0 0 0" xyz="0 0 0"/>
    </collision>
    <inertial>
      <mass value="0.1"/>
      <inertia ixx="0.0001667" iyy="0.0001667" izz="0.0001667"
               ixy="0.0" ixz="0.0" iyz="0.0"/>
      <origin rpy="0 0 0" xyz="0 0 0"/>
    </inertial>
  </link>

<!-- Joint definitions -->
  <!-- FIXME: should probably change 'continuous' joints to 'revolute' joints
              and add joint limits -->
  <joint name="seg_0_left_hip_joint" type="continuous">
    <axis xyz="0 0 1"/>
    <parent link="seg_0"/>
    <child link="seg_0_left_upper_leg_link"/>
    <origin rpy="0 0 0" xyz="0 0.1524 0"/>
    <dynamics friction="0.1" damping="0.5"/>
  </joint>

  <joint name="seg_0_right_hip_joint" type="continuous">
    <axis xyz="0 0 1"/>
    <parent link="seg_0"/>
    <child link="seg_0_right_upper_leg_link"/>
    <origin rpy="0 0 0" xyz="0 -0.1524 0"/>
    <dynamics friction="0.1" damping="0.5"/>
  </joint>

  <joint name="seg_0_left_knee_joint" type="continuous">
    <axis xyz="1 0 0"/>
    <parent link="seg_0_left_upper_leg_link"/>
    <child link="seg_0_left_lower_leg_link"/>
    <origin rpy="0 0 0" xyz="0 0.5 0"/>
    <dynamics friction="0.1" damping="0.5"/>
  </joint>

  <joint name="seg_0_right_knee_joint" type="continuous">
    <axis xyz="1 0 0"/>
    <parent link="seg_0_right_upper_leg_link"/>
    <child link="seg_0_right_lower_leg_link"/>
    <origin rpy="0 0 0" xyz="0 -0.5 0"/>
    <dynamics friction="0.1" damping="0.5"/>
  </joint>

  <joint name="seg_0_left_foot_joint" type="revolute">
    <axis xyz="1 0 0"/>
    <parent link="seg_0_left_lower_leg_link"/>
    <child link="seg_0_left_foot_link"/>
    <origin rpy="0 0 0" xyz="0 0 -0.5"/>
    <dynamics friction="0.1" damping="0.5"/>
    <limit upper="0.1" lower="-1.5708" effort="500.0" velocity="500.0"/>
  </joint>

  <joint name="seg_0_right_foot_joint" type="revolute">
    <axis xyz="1 0 0"/>
    <parent link="seg_0_right_lower_leg_link"/>
    <child link="seg_0_right_foot_link"/>
    <origin rpy="0 0 0" xyz="0 0 -0.5"/>
    <dynamics friction="0.1" damping="0.5"/>
    <limit upper="1.5708" lower="-0.1" effort="500.0" velocity="500.0"/>
  </joint>

  <!-- segment 1 -->
  <!-- FIXME: should probably change 'continuous' joints to 'revolute' joints
              and add joint limits -->
  <joint name="seg_1_left_hip_joint" type="continuous">
    <axis xyz="0 0 1"/>
    <parent link="seg_1"/>
    <child link="seg_1_left_upper_leg_link"/>
    <origin rpy="0 0 0" xyz="0 0.1524 0"/>
    <dynamics friction="0.1" damping="0.5"/>
  </joint>

  <joint name="seg_1_right_hip_joint" type="continuous">
    <axis xyz="0 0 1"/>
    <parent link="seg_1"/>
    <child link="seg_1_right_upper_leg_link"/>
    <origin rpy="0 0 0" xyz="0 -0.1524 0"/>
    <dynamics friction="0.1" damping="0.5"/>
  </joint>

  <joint name="seg_1_left_knee_joint" type="continuous">
    <axis xyz="1 0 0"/>
    <parent link="seg_1_left_upper_leg_link"/>
    <child link="seg_1_left_lower_leg_link"/>
    <origin rpy="0 0 0" xyz="0 0.5 0"/>
    <dynamics friction="0.1" damping="0.5"/>
  </joint>

  <joint name="seg_1_right_knee_joint" type="continuous">
    <axis xyz="1 0 0"/>
    <parent link="seg_1_right_upper_leg_link"/>
    <child link="seg_1_right_lower_leg_link"/>
    <origin rpy="0 0 0" xyz="0 -0.5 0"/>
    <dynamics friction="0.1" damping="0.5"/>
  </joint>

  <joint name="seg_1_left_foot_joint" type="revolute">
    <axis xyz="1 0 0"/>
    <parent link="seg_1_left_lower_leg_link"/>
    <child link="seg_1_left_foot_link"/>
    <origin rpy="0 0 0" xyz="0 0 -0.5"/>
    <dynamics friction="0.1" damping="0.5"/>
    <limit upper="0.1" lower="-1.5708" effort="500.0" velocity="500.0"/>
  </joint>

  <joint name="seg_1_right_foot_joint" type="revolute">
    <axis xyz="1 0 0"/>
    <parent link="seg_1_right_lower_leg_link"/>
    <child link="seg_1_right_foot_link"/>
    <origin rpy="0 0 0" xyz="0 0 -0.5"/>
    <dynamics friction="0.1" damping="0.5"/>
    <limit upper="1.5708" lower="-0.1" effort="500.0" velocity="500.0"/>
  </joint>

  <!-- segment 2 -->
  <!-- FIXME: should probably change 'continuous' joints to 'revolute' joints
              and add joint limits -->
  <joint name="seg_2_left_hip_joint" type="continuous">
    <axis xyz="0 0 1"/>
    <parent link="seg_2"/>
    <child link="seg_2_left_upper_leg_link"/>
    <origin rpy="0 0 0" xyz="0 0.1524 0"/>
    <dynamics friction="0.1" damping="0.5"/>
  </joint>

  <joint name="seg_2_right_hip_joint" type="continuous">
    <axis xyz="0 0 1"/>
    <parent link="seg_2"/>
    <child link="seg_2_right_upper_leg_link"/>
    <origin rpy="0 0 0" xyz="0 -0.1524 0"/>
    <dynamics friction="0.1" damping="0.5"/>
  </joint>

  <joint name="seg_2_left_knee_joint" type="continuous">
    <axis xyz="1 0 0"/>
    <parent link="seg_2_left_upper_leg_link"/>
    <child link="seg_2_left_lower_leg_link"/>
    <origin rpy="0 0 0" xyz="0 0.5 0"/>
    <dynamics friction="0.1" damping="0.5"/>
  </joint>

  <joint name="seg_2_right_knee_joint" type="continuous">
    <axis xyz="1 0 0"/>
    <parent link="seg_2_right_upper_leg_link"/>
    <child link="seg_2_right_lower_leg_link"/>
    <origin rpy="0 0 0" xyz="0 -0.5 0"/>
    <dynamics friction="0.1" damping="0.5"/>
  </joint>

  <joint name="seg_2_left_foot_joint" type="revolute">
    <axis xyz="1 0 0"/>
    <parent link="seg_2_left_lower_leg_link"/>
    <child link="seg_2_left_foot_link"/>
    <origin rpy="0 0 0" xyz="0 0 -0.5"/>
    <dynamics friction="0.1" damping="0.5"/>
    <limit upper="0.1" lower="-1.5708" effort="500.0" velocity="500.0"/>
  </joint>

  <joint name="seg_2_right_foot_joint" type="revolute">
    <axis xyz="1 0 0"/>
    <parent link="seg_2_right_lower_leg_link"/>
    <child link="seg_2_right_foot_link"/>
    <origin rpy="0 0 0" xyz="0 0 -0.5"/>
    <dynamics friction="0.1" damping="0.5"/>
    <limit upper="1.5708" lower="-0.1" effort="500.0" velocity="500.0"/>
  </joint>

  <!-- segment 3 -->
  <!-- FIXME: should probably change 'continuous' joints to 'revolute' joints
              and add joint limits -->
  <joint name="seg_3_left_hip_joint" type="continuous">
    <axis xyz="0 0 1"/>
    <parent link="seg_3"/>
    <child link="seg_3_left_upper_leg_link"/>
    <origin rpy="0 0 0" xyz="0 0.1524 0"/>
    <dynamics friction="0.1" damping="0.5"/>
  </joint>

  <joint name="seg_3_right_hip_joint" type="continuous">
    <axis xyz="0 0 1"/>
    <parent link="seg_3"/>
    <child link="seg_3_right_upper_leg_link"/>
    <origin rpy="0 0 0" xyz="0 -0.1524 0"/>
    <dynamics friction="0.1" damping="0.5"/>
  </joint>

  <joint name="seg_3_left_knee_joint" type="continuous">
    <axis xyz="1 0 0"/>
    <parent link="seg_3_left_upper_leg_link"/>
    <child link="seg_3_left_lower_leg_link"/>
    <origin rpy="0 0 0" xyz="0 0.5 0"/>
    <dynamics friction="0.1" damping="0.5"/>
  </joint>

  <joint name="seg_3_right_knee_joint" type="continuous">
    <axis xyz="1 0 0"/>
    <parent link="seg_3_right_upper_leg_link"/>
    <child link="seg_3_right_lower_leg_link"/>
    <origin rpy="0 0 0" xyz="0 -0.5 0"/>
    <dynamics friction="0.1" damping="0.5"/>
  </joint>

  <joint name="seg_3_left_foot_joint" type="revolute">
    <axis xyz="1 0 0"/>
    <parent link="seg_3_left_lower_leg_link"/>
    <child link="seg_3_left_foot_link"/>
    <origin rpy="0 0 0" xyz="0 0 -0.5"/>
    <dynamics friction="0.1" damping="0.5"/>
    <limit upper="0.1" lower="-1.5708" effort="500.0" velocity="500.0"/>
  </joint>

  <joint name="seg_3_right_foot_joint" type="revolute">
    <axis xyz="1 0 0"/>
    <parent link="seg_3_right_lower_leg_link"/>
    <child link="seg_3_right_foot_link"/>
    <origin rpy="0 0 0" xyz="0 0 -0.5"/>
    <dynamics friction="0.1" damping="0.5"/>
    <limit upper="1.5708" lower="-0.1" effort="500.0" velocity="500.0"/>
  </joint>

  <!-- segment 4 -->
  <!-- FIXME: should probably change 'continuous' joints to 'revolute' joints
              and add joint limits -->
  <joint name="seg_4_left_hip_joint" type="continuous">
    <axis xyz="0 0 1"/>
    <parent link="seg_4"/>
    <child link="seg_4_left_upper_leg_link"/>
    <origin rpy="0 0 0" xyz="0 0.1524 0"/>
    <dynamics friction="0.1" damping="0.5"/>
  </joint>

  <joint name="seg_4_right_hip_joint" type="continuous">
    <axis xyz="0 0 1"/>
    <parent link="seg_4"/>
    <child link="seg_4_right_upper_leg_link"/>
    <origin rpy="0 0 0" xyz="0 -0.1524 0"/>
    <dynamics friction="0.1" damping="0.5"/>
  </joint>

  <joint name="seg_4_left_knee_joint" type="continuous">
    <axis xyz="1 0 0"/>
    <parent link="seg_4_left_upper_leg_link"/>
    <child link="seg_4_left_lower_leg_link"/>
    <origin rpy="0 0 0" xyz="0 0.5 0"/>
    <dynamics friction="0.1" damping="0.5"/>
  </joint>

  <joint name="seg_4_right_knee_joint" type="continuous">
    <axis xyz="1 0 0"/>
    <parent link="seg_4_right_upper_leg_link"/>
    <child link="seg_4_right_lower_leg_link"/>
    <origin rpy="0 0 0" xyz="0 -0.5 0"/>
    <dynamics friction="0.1" damping="0.5"/>
  </joint>

  <joint name="seg_4_left_foot_joint" type="revolute">
    <axis xyz="1 0 0"/>
    <parent link="seg_4_left_lower_leg_link"/>
    <child link="seg_4_left_foot_link"/>
    <origin rpy="0 0 0" xyz="0 0 -0.5"/>
    <dynamics friction="0.1" damping="0.5"/>
    <limit upper="0.1" lower="-1.5708" effort="500.0" velocity="500.0"/>
  </joint>

  <joint name="seg_4_right_foot_joint" type="revolute">
    <axis xyz="1 0 0"/>
    <parent link="seg_4_right_lower_leg_link"/>
    <child link="seg_4_right_foot_link"/>
    <origin rpy="0 0 0" xyz="0 0 -0.5"/>
    <dynamics friction="0.1" damping="0.5"/>
    <limit upper="1.5708" lower="-0.1" effort="500.0" velocity="500.0"/>
  </joint>

  <!-- segment 5 -->
  <!-- FIXME: should probably change 'continuous' joints to 'revolute' joints
              and add joint limits -->
  <joint name="seg_5_left_hip_joint" type="continuous">
    <axis xyz="0 0 1"/>
    <parent link="seg_5"/>
    <child link="seg_5_left_upper_leg_link"/>
    <origin rpy="0 0 0" xyz="0 0.1524 0"/>
    <dynamics friction="0.1" damping="0.5"/>
  </joint>

  <joint name="seg_5_right_hip_joint" type="continuous">
    <axis xyz="0 0 1"/>
    <parent link="seg_5"/>
    <child link="seg_5_right_upper_leg_link"/>
    <origin rpy="0 0 0" xyz="0 -0.1524 0"/>
    <dynamics friction="0.1" damping="0.5"/>
  </joint>

  <joint name="seg_5_left_knee_joint" type="continuous">
    <axis xyz="1 0 0"/>
    <parent link="seg_5_left_upper_leg_link"/>
    <child link="seg_5_left_lower_leg_link"/>
    <origin rpy="0 0 0" xyz="0 0.5 0"/>
    <dynamics friction="0.1" damping="0.5"/>
  </joint>

  <joint name="seg_5_right_knee_joint" type="continuous">
    <axis xyz="1 0 0"/>
    <parent link="seg_5_right_upper_leg_link"/>
    <child link="seg_5_right_lower_leg_link"/>
    <origin rpy="0 0 0" xyz="0 -0.5 0"/>
    <dynamics friction="0.1" damping="0.5"/>
  </joint>

  <joint name="seg_5_left_foot_joint" type="revolute">
    <axis xyz="1 0 0"/>
    <parent link="seg_5_left_lower_leg_link"/>
    <child link="seg_5_left_foot_link"/>
    <origin rpy="0 0 0" xyz="0 0 -0.5"/>
    <dynamics friction="0.1" damping="0.5"/>
    <limit upper="0.1" lower="-1.5708" effort="500.0" velocity="500.0"/>
  </joint>

  <joint name="seg_5_right_foot_joint" type="revolute">
    <axis xyz="1 0 0"/>
    <parent link="seg_5_right_lower_leg_link"/>
    <child link="seg_5_right_foot_link"/>
    <origin rpy="0 0 0" xyz="0 0 -0.5"/>
    <dynamics friction="0.1" damping="0.5"/>
    <limit upper="1.5708" lower="-0.1" effort="500.0" velocity="500.0"/>
  </joint>

  <!-- connectors -->
  <joint name="seg_0_to_connector_0_b" type="prismatic">
    <axis xyz="0 0 1"/>
    <parent link="seg_0"/>
    <child link="connector_0_b"/>
    <origin rpy="0 0 0" xyz="0 0 0"/>
    <dynamics friction="0.1" damping="10.0"/>
    <limit upper="0.08" lower="-0.08" effort="100.0" velocity="15.0"/>
  </joint>

  <joint name="connector_0_b_to_connector_0" type="revolute">
    <axis xyz="0 1 0"/>
    <parent link="connector_0_b"/>
    <child link="connector_0"/>
    <origin rpy="0 0 0" xyz="-0.1524 0 0"/>
    <dynamics friction="0.1" damping="10.0"/>
    <limit upper="0.26" lower="-0.26" effort="100.0" velocity="15.0"/>
  </joint>

  <joint name="connector_0_to_seg_1" type="prismatic">
    <axis xyz="-1 0 0"/>
    <parent link="connector_0"/>
    <child link="seg_1"/>
    <origin rpy="0 0 0" xyz="-0.3048 0 0"/>
    <dynamics friction="0.1" damping="10.0"/>
    <limit upper="0.3048" lower="0.0" effort="100.0" velocity="15.0"/>
  </joint>

  <joint name="seg_1_to_connector_1_b" type="prismatic">
    <axis xyz="0 0 1"/>
    <parent link="seg_1"/>
    <child link="connector_1_b"/>
    <origin rpy="0 0 0" xyz="0 0 0"/>
    <dynamics friction="0.1" damping="10.0"/>
    <limit upper="0.08" lower="-0.08" effort="100.0" velocity="15.0"/>
  </joint>

  <joint name="connector_1_b_to_connector_1" type="revolute">
    <axis xyz="0 1 0"/>
    <parent link="connector_1_b"/>
    <child link="connector_1"/>
    <origin rpy="0 0 0" xyz="-0.1524 0 0"/>
    <dynamics friction="0.1" damping="10.0"/>
    <limit upper="0.26" lower="-0.26" effort="100.0" velocity="15.0"/>
  </joint>

  <joint name="connector_1_to_seg_2" type="prismatic">
    <axis xyz="-1 0 0"/>
    <parent link="connector_1"/>
    <child link="seg_2"/>
    <origin rpy="0 0 0" xyz="-0.3048 0 0"/>
    <dynamics friction="0.1" damping="10.0"/>
    <limit upper="0.3048" lower="0.0" effort="100.0" velocity="15.0"/>
  </joint>

  <joint name="seg_2_to_connector_2_b" type="prismatic">
    <axis xyz="0 0 1"/>
    <parent link="seg_2"/>
    <child link="connector_2_b"/>
    <origin rpy="0 0 0" xyz="0 0 0"/>
    <dynamics friction="0.1" damping="10.0"/>
    <limit upper="0.08" lower="-0.08" effort="100.0" velocity="15.0"/>
  </joint>

  <joint name="connector_2_b_to_connector_2" type="revolute">
    <axis xyz="0 1 0"/>
    <parent link="connector_2_b"/>
    <child link="connector_2"/>
    <origin rpy="0 0 0" xyz="-0.1524 0 0"/>
    <dynamics friction="0.1" damping="10.0"/>
    <limit upper="0.26" lower="-0.26" effort="100.0" velocity="15.0"/>
  </joint>

  <joint name="connector_2_to_seg_3" type="prismatic">
    <axis xyz="-1 0 0"/>
    <parent link="connector_2"/>
    <child link="seg_3"/>
    <origin rpy="0 0 0" xyz="-0.3048 0 0"/>
    <dynamics friction="0.1" damping="10.0"/>
    <limit upper="0.3048" lower="-0.0" effort="100.0" velocity="15.0"/>
  </joint>

  <joint name="seg_3_to_connector_3_b" type="prismatic">
    <axis xyz="0 0 1"/>
    <parent link="seg_3"/>
    <child link="connector_3_b"/>
    <origin rpy="0 0 0" xyz="0 0 0"/>
    <dynamics friction="0.1" damping="10.0"/>
    <limit upper="0.08" lower="-0.08" effort="100.0" velocity="15.0"/>
  </joint>

  <joint name="connector_3_b_to_connector_3" type="revolute">
    <axis xyz="0 1 0"/>
    <parent link="connector_3_b"/>
    <child link="connector_3"/>
    <origin rpy="0 0 0" xyz="-0.1524 0 0"/>
    <dynamics friction="0.1" damping="10.0"/>
    <limit upper="0.26" lower="-0.26" effort="100.0" velocity="15.0"/>
  </joint>

  <joint name="connector_3_to_seg_4" type="prismatic">
    <axis xyz="-1 0 0"/>
    <parent link="connector_3"/>
    <child link="seg_4"/>
    <origin rpy="0 0 0" xyz="-0.3048 0 0"/>
    <dynamics friction="0.1" damping="10.0"/>
    <limit upper="0.3048" lower="-0.0" effort="100.0" velocity="15.0"/>
  </joint>

  <joint name="seg_4_to_connector_4_b" type="prismatic">
    <axis xyz="0 0 1"/>
    <parent link="seg_4"/>
    <child link="connector_4_b"/>
    <origin rpy="0 0 0" xyz="0 0 0"/>3
    <dynamics friction="0.1" damping="10.0"/>
    <limit upper="0.08" lower="-0.08" effort="100.0" velocity="15.0"/>
  </joint>

  <joint name="connector_4_b_to_connector_4" type="revolute">
    <axis xyz="0 1 0"/>
    <parent link="connector_4_b"/>
    <child link="connector_4"/>
    <origin rpy="0 0 0" xyz="-0.1524 0 0"/>
    <dynamics friction="0.1" damping="10.0"/>
    <limit upper="0.26" lower="-0.26" effort="100.0" velocity="15.0"/>
  </joint>

  <joint name="connector_4_to_seg_5" type="prismatic">
    <axis xyz="-1 0 0"/>
    <parent link="connector_4"/>
    <child link="seg_5"/>
    <origin rpy="0 0 0" xyz="-0.3048 0 0"/>
    <dynamics friction="0.1" damping="10.0"/>
    <limit upper="0.3048" lower="-0.0" effort="100.0" velocity="15.0"/>
  </joint>

<!-- Gazebo definitions - only used in Gazebo simulation -->

  <!-- segment 0 -->
  <gazebo reference="seg_0">
    <material>Gazebo/White</material>
    <mu1>1.0</mu1>
    <mu2>1.0</mu2>
    <kp>10000000.0</kp>
    <kd>1.0</kd>
  </gazebo>

  <gazebo reference="seg_0_left_upper_leg_link">
    <material>Gazebo/Black</material>
    <selfCollide>True</selfCollide>
    <mu1>1.0</mu1>
    <mu2>1.0</mu2>
    <kp>10000000.0</kp>
    <kd>1.0</kd>
  </gazebo>

  <gazebo reference="seg_0_right_upper_leg_link">
    <material>Gazebo/Black</material>
    <selfCollide>True</selfCollide>
    <mu1>1.0</mu1>
    <mu2>1.0</mu2>
    <kp>10000000.0</kp>
    <kd>1.0</kd>
  </gazebo>

  <gazebo reference="seg_0_left_lower_leg_link">
    <material>Gazebo/Orange</material>
    <selfCollide>True</selfCollide>
    <mu1>1.0</mu1>
    <mu2>1.0</mu2>
    <kp>10000000.0</kp>
    <kd>1.0</kd>
  </gazebo>

  <gazebo reference="seg_0_right_lower_leg_link">
    <material>Gazebo/Orange</material>
    <selfCollide>True</selfCollide>
    <mu1>1.0</mu1>
    <mu2>1.0</mu2>
    <kp>10000000.0</kp>
    <kd>1.0</kd>
  </gazebo>

  <!-- kp and kd for rubber -->
  <gazebo reference="seg_0_left_foot_link">
    <material>Gazebo/Black</material>
    <mu1>10000.0</mu1>
    <mu2>10000.0</mu2>
    <kp>10000.0</kp>
    <kd>100.0</kd>
    <maxVel>0.5</maxVel>
    <minDepth>0.009</minDepth>
  </gazebo>

  <!-- kp and kd for rubber -->
  <gazebo reference="seg_0_right_foot_link">
    <material>Gazebo/Black</material>
    <mu1>10000.0</mu1>
    <mu2>10000.0</mu2>
    <kp>10000.0</kp>
    <kd>100.0</kd>
    <maxVel>0.5</maxVel>
    <minDepth>0.009</minDepth>
  </gazebo>

  <gazebo reference="seg_0_left_hip_joint">
    <implicitSpringDamper>True</implicitSpringDamper>
  </gazebo>

  <gazebo reference="seg_0_right_hip_joint">
    <implicitSpringDamper>True</implicitSpringDamper>
  </gazebo>

  <gazebo reference="seg_0_left_knee_joint">
    <implicitSpringDamper>True</implicitSpringDamper>
  </gazebo>

  <gazebo reference="seg_0_right_knee_joint">
    <implicitSpringDamper>True</implicitSpringDamper>
  </gazebo>

  <gazebo reference="seg_0_left_foot_joint">
    <implicitSpringDamper>True</implicitSpringDamper>
  </gazebo>

  <gazebo reference="seg_0_right_foot_joint">
    <implicitSpringDamper>True</implicitSpringDamper>
  </gazebo>

  <gazebo>
    <plugin name="boilerplate_motor_plugin"
            filename="libboilerplate_motor_plugin.so">
      <actuatorJoint>seg_0_left_hip_joint</actuatorJoint>
      <maxTorque>40.0</maxTorque>
      <posPidPGain>85.0</posPidPGain>
      <posPidIGain>15.0</posPidIGain>
      <posPidDGain>25.0</posPidDGain>
      <posPidIMax>30.0</posPidIMax>
      <posPidIMin>-30.0</posPidIMin>
      <initialPosition>0.0</initialPosition>
      <cmdPosTopic>seg0_leftleg_to_lefthip</cmdPosTopic>
      <anglePosTopic>seg0_lefthip_to_leftleg</anglePosTopic>
    </plugin>
  </gazebo>

  <gazebo>
    <plugin name="boilerplate_motor_plugin"
            filename="libboilerplate_motor_plugin.so">
      <actuatorJoint>seg_0_right_hip_joint</actuatorJoint>
      <maxTorque>40.0</maxTorque>
      <posPidPGain>85.0</posPidPGain>
      <posPidIGain>15.0</posPidIGain>
      <posPidDGain>25.0</posPidDGain>
      <posPidIMax>30.0</posPidIMax>
      <posPidIMin>-30.0</posPidIMin>
      <initialPosition>0.0</initialPosition>
      <cmdPosTopic>seg0_rightleg_to_righthip</cmdPosTopic>
      <anglePosTopic>seg0_righthip_to_rightleg</anglePosTopic>
    </plugin>
  </gazebo>

  <gazebo>
    <plugin name="boilerplate_motor_plugin"
            filename="libboilerplate_motor_plugin.so">
      <actuatorJoint>seg_0_left_knee_joint</actuatorJoint>
      <maxTorque>40.0</maxTorque>
      <posPidPGain>85.0</posPidPGain>
      <posPidIGain>15.0</posPidIGain>
      <posPidDGain>25.0</posPidDGain>
      <posPidIMax>30.0</posPidIMax>
      <posPidIMin>-30.0</posPidIMin>
      <initialPosition>0.0</initialPosition>
      <cmdPosTopic>seg0_leftleg_to_leftknee</cmdPosTopic>
      <anglePosTopic>seg0_leftknee_to_leftleg</anglePosTopic>
    </plugin>
  </gazebo>

  <gazebo>
    <plugin name="boilerplate_motor_plugin"
            filename="libboilerplate_motor_plugin.so">
      <actuatorJoint>seg_0_right_knee_joint</actuatorJoint>
      <maxTorque>40.0</maxTorque>
      <posPidPGain>85.0</posPidPGain>
      <posPidIGain>15.0</posPidIGain>
      <posPidDGain>25.0</posPidDGain>
      <posPidIMax>30.0</posPidIMax>
      <posPidIMin>-30.0</posPidIMin>
      <initialPosition>0.0</initialPosition>
      <cmdPosTopic>seg0_rightleg_to_rightknee</cmdPosTopic>
      <anglePosTopic>seg0_rightknee_to_rightleg</anglePosTopic>
    </plugin>
  </gazebo>

  <!-- segment 1 -->
  <gazebo reference="seg_1">
    <material>Gazebo/White</material>
    <mu1>1.0</mu1>
    <mu2>1.0</mu2>
    <kp>10000000.0</kp>
    <kd>1.0</kd>
  </gazebo>

  <gazebo reference="seg_1_left_upper_leg_link">
    <material>Gazebo/Black</material>
    <selfCollide>True</selfCollide>
    <mu1>1.0</mu1>
    <mu2>1.0</mu2>
    <kp>10000000.0</kp>
    <kd>1.0</kd>
  </gazebo>

  <gazebo reference="seg_1_right_upper_leg_link">
    <material>Gazebo/Black</material>
    <selfCollide>True</selfCollide>
    <mu1>1.0</mu1>
    <mu2>1.0</mu2>
    <kp>10000000.0</kp>
    <kd>1.0</kd>
  </gazebo>

  <gazebo reference="seg_1_left_lower_leg_link">
    <material>Gazebo/Orange</material>
    <selfCollide>True</selfCollide>1000
    <mu1>1.0</mu1>
    <mu2>1.0</mu2>
    <kp>10000000.0</kp>
    <kd>1.0</kd>
  </gazebo>

  <gazebo reference="seg_1_right_lower_leg_link">
    <material>Gazebo/Orange</material>
    <selfCollide>True</selfCollide>
    <mu1>1.0</mu1>
    <mu2>1.0</mu2>
    <kp>10000000.0</kp>
    <kd>1.0</kd>
  </gazebo>

  <!-- kp and kd for rubber -->
  <gazebo reference="seg_1_left_foot_link">
    <material>Gazebo/Black</material>
    <mu1>10000.0</mu1>
    <mu2>10000.0</mu2>
    <kp>10000.0</kp>
    <kd>100.0</kd>
    <maxVel>0.5</maxVel>
    <minDepth>0.009</minDepth>
  </gazebo>

  <!-- kp and kd for rubber -->
  <gazebo reference="seg_1_right_foot_link">
    <material>Gazebo/Black</material>
    <mu1>10000.0</mu1>
    <mu2>10000.0</mu2>
    <kp>10000.0</kp>
    <kd>100.0</kd>
    <maxVel>0.5</maxVel>
    <minDepth>0.009</minDepth>
  </gazebo>

  <gazebo reference="seg_1_left_hip_joint">
    <implicitSpringDamper>True</implicitSpringDamper>
  </gazebo>

  <gazebo reference="seg_1_right_hip_joint">
    <implicitSpringDamper>True</implicitSpringDamper>
  </gazebo>

  <gazebo reference="seg_1_left_knee_joint">
    <implicitSpringDamper>True</implicitSpringDamper>
  </gazebo>

  <gazebo reference="seg_1_right_knee_joint">
    <implicitSpringDamper>True</implicitSpringDamper>
  </gazebo>

  <gazebo reference="seg_1_left_foot_joint">
    <implicitSpringDamper>True</implicitSpringDamper>
  </gazebo>

  <gazebo reference="seg_1_right_foot_joint">
    <implicitSpringDamper>True</implicitSpringDamper>
  </gazebo>

  <gazebo>
    <plugin name="boilerplate_motor_plugin"
            filename="libboilerplate_motor_plugin.so">
      <actuatorJoint>seg_1_left_hip_joint</actuatorJoint>
      <maxTorque>40.0</maxTorque>
      <posPidPGain>85.0</posPidPGain>
      <posPidIGain>15.0</posPidIGain>
      <posPidDGain>25.0</posPidDGain>
      <posPidIMax>30.0</posPidIMax>
      <posPidIMin>-30.0</posPidIMin>
      <initialPosition>0.0</initialPosition>
      <cmdPosTopic>seg1_leftleg_to_lefthip</cmdPosTopic>
      <anglePosTopic>seg1_lefthip_to_leftleg</anglePosTopic>
    </plugin>
  </gazebo>

  <gazebo>
    <plugin name="boilerplate_motor_plugin"
            filename="libboilerplate_motor_plugin.so">
      <actuatorJoint>seg_1_right_hip_joint</actuatorJoint>
      <maxTorque>40.0</maxTorque>
      <posPidPGain>85.0</posPidPGain>
      <posPidIGain>15.0</posPidIGain>
      <posPidDGain>25.0</posPidDGain>
      <posPidIMax>30.0</posPidIMax>
      <posPidIMin>-30.0</posPidIMin>
      <initialPosition>0.0</initialPosition>
      <cmdPosTopic>seg1_rightleg_to_righthip</cmdPosTopic>
      <anglePosTopic>seg1_righthip_to_rightleg</anglePosTopic>
    </plugin>
  </gazebo>

  <gazebo>
    <plugin name="boilerplate_motor_plugin"
            filename="libboilerplate_motor_plugin.so">
      <actuatorJoint>seg_1_left_knee_joint</actuatorJoint>
      <maxTorque>40.0</maxTorque>
      <posPidPGain>85.0</posPidPGain>
      <posPidIGain>15.0</posPidIGain>
      <posPidDGain>25.0</posPidDGain>
      <posPidIMax>30.0</posPidIMax>
      <posPidIMin>-30.0</posPidIMin>
      <initialPosition>0.0</initialPosition>
      <cmdPosTopic>seg1_leftleg_to_leftknee</cmdPosTopic>
      <anglePosTopic>seg1_leftknee_to_leftleg</anglePosTopic>
    </plugin>
  </gazebo>

  <gazebo>
    <plugin name="boilerplate_motor_plugin"
            filename="libboilerplate_motor_plugin.so">
      <actuatorJoint>seg_1_right_knee_joint</actuatorJoint>
      <maxTorque>40.0</maxTorque>
      <posPidPGain>85.0</posPidPGain>
      <posPidIGain>15.0</posPidIGain>
      <posPidDGain>25.0</posPidDGain>
      <posPidIMax>30.0</posPidIMax>
      <posPidIMin>-30.0</posPidIMin>
      <initialPosition>0.0</initialPosition>
      <cmdPosTopic>seg1_rightleg_to_rightknee</cmdPosTopic>
      <anglePosTopic>seg1_rightknee_to_rightleg</anglePosTopic>
    </plugin>
  </gazebo>

  <!-- segment 2 -->
  <gazebo reference="seg_2">
    <material>Gazebo/White</material>
  </gazebo>

  <gazebo reference="seg_2_left_upper_leg_link">
    <material>Gazebo/Black</material>
    <selfCollide>True</selfCollide>
    <mu1>1.0</mu1>
    <mu2>1.0</mu2>
    <kp>10000000.0</kp>
    <kd>1.0</kd>
  </gazebo>

  <gazebo reference="seg_2_right_upper_leg_link">
    <material>Gazebo/Black</material>
    <selfCollide>True</selfCollide>
    <mu1>1.0</mu1>
    <mu2>1.0</mu2>
    <kp>10000000.0</kp>
    <kd>1.0</kd>
  </gazebo>

  <gazebo reference="seg_2_left_lower_leg_link">
    <material>Gazebo/Orange</material>
    <selfCollide>True</selfCollide>
    <mu1>1.0</mu1>
    <mu2>1.0</mu2>
    <kp>10000000.0</kp>
    <kd>1.0</kd>
  </gazebo>

  <gazebo reference="seg_2_right_lower_leg_link">
    <material>Gazebo/Orange</material>
    <selfCollide>True</selfCollide>
    <mu1>1.0</mu1>
    <mu2>1.0</mu2>
    <kp>10000000.0</kp>
    <kd>1.0</kd>
  </gazebo>

  <!-- kp and kd for rubber -->
  <gazebo reference="seg_2_left_foot_link">
    <material>Gazebo/Black</material>
    <mu1>10000.0</mu1>
    <mu2>10000.0</mu2>
    <kp>10000.0</kp>
    <kd>100.0</kd>
    <maxVel>0.5</maxVel>
    <minDepth>0.009</minDepth>
  </gazebo>

  <gazebo reference="seg_2_right_foot_link">
    <material>Gazebo/Black</material>
    <mu1>10000.0</mu1>
    <mu2>10000.0</mu2>
    <kp>10000.0</kp>
    <kd>100.0</kd>
    <maxVel>0.5</maxVel>
    <minDepth>0.009</minDepth>
  </gazebo>

  <gazebo reference="seg_2_left_hip_joint">
    <implicitSpringDamper>True</implicitSpringDamper>
  </gazebo>

  <gazebo reference="seg_2_right_hip_joint">
    <implicitSpringDamper>True</implicitSpringDamper>
  </gazebo>

  <gazebo reference="seg_2_left_knee_joint">
    <implicitSpringDamper>True</implicitSpringDamper>
  </gazebo>

  <gazebo reference="seg_2_right_knee_joint">
    <implicitSpringDamper>True</implicitSpringDamper>
  </gazebo>

  <gazebo reference="seg_2_left_foot_joint">
    <implicitSpringDamper>True</implicitSpringDamper>
  </gazebo>

  <gazebo reference="seg_2_right_foot_joint">
    <implicitSpringDamper>True</implicitSpringDamper>
  </gazebo>

  <gazebo>
    <plugin name="boilerplate_motor_plugin"
            filename="libboilerplate_motor_plugin.so">
      <actuatorJoint>seg_2_left_hip_joint</actuatorJoint>
      <maxTorque>40.0</maxTorque>
      <posPidPGain>85.0</posPidPGain>
      <posPidIGain>15.0</posPidIGain>
      <posPidDGain>25.0</posPidDGain>
      <posPidIMax>30.0</posPidIMax>
      <posPidIMin>-30.0</posPidIMin>
      <initialPosition>0.0</initialPosition>
      <cmdPosTopic>seg2_leftleg_to_lefthip</cmdPosTopic>
      <anglePosTopic>seg2_lefthip_to_leftleg</anglePosTopic>
    </plugin>
  </gazebo>

  <gazebo>
    <plugin name="boilerplate_motor_plugin"
            filename="libboilerplate_motor_plugin.so">
      <actuatorJoint>seg_2_right_hip_joint</actuatorJoint>
      <maxTorque>40.0</maxTorque>
      <posPidPGain>85.0</posPidPGain>
      <posPidIGain>15.0</posPidIGain>
      <posPidDGain>25.0</posPidDGain>
      <posPidIMax>30.0</posPidIMax>
      <posPidIMin>-30.0</posPidIMin>
      <initialPosition>0.0</initialPosition>
      <cmdPosTopic>seg2_rightleg_to_righthip</cmdPosTopic>
      <anglePosTopic>seg2_righthip_to_rightleg</anglePosTopic>
    </plugin>
  </gazebo>

  <gazebo>
    <plugin name="boilerplate_motor_plugin"
            filename="libboilerplate_motor_plugin.so">
      <actuatorJoint>seg_2_left_knee_joint</actuatorJoint>
      <maxTorque>40.0</maxTorque>
      <posPidPGain>85.0</posPidPGain>
      <posPidIGain>15.0</posPidIGain>
      <posPidDGain>25.0</posPidDGain>
      <posPidIMax>30.0</posPidIMax>
      <posPidIMin>-30.0</posPidIMin>
      <initialPosition>0.0</initialPosition>
      <cmdPosTopic>seg2_leftleg_to_leftknee</cmdPosTopic>
      <anglePosTopic>seg2_leftknee_to_leftleg</anglePosTopic>
    </plugin>
  </gazebo>

  <gazebo>
    <plugin name="boilerplate_motor_plugin"
            filename="libboilerplate_motor_plugin.so">
      <actuatorJoint>seg_2_right_knee_joint</actuatorJoint>
      <maxTorque>40.0</maxTorque>
      <posPidPGain>85.0</posPidPGain>
      <posPidIGain>15.0</posPidIGain>
      <posPidDGain>25.0</posPidDGain>
      <posPidIMax>30.0</posPidIMax>
      <posPidIMin>-30.0</posPidIMin>
      <initialPosition>0.0</initialPosition>
      <cmdPosTopic>seg2_rightleg_to_rightknee</cmdPosTopic>
      <anglePosTopic>seg2_rightknee_to_rightleg</anglePosTopic>
    </plugin>
  </gazebo>

  <!-- segment 3 -->
  <gazebo reference="seg_3">
    <material>Gazebo/White</material>
    <mu1>1.0</mu1>
    <mu2>1.0</mu2>
    <kp>10000000.0</kp>
    <kd>100.0</kd>
  </gazebo>

  <gazebo reference="seg_3_left_upper_leg_link">
    <material>Gazebo/Black</material>
    <selfCollide>True</selfCollide>
    <mu1>1.0</mu1>
    <mu2>1.0</mu2>
    <kp>10000000.0</kp>
    <kd>1.0</kd>
  </gazebo>

  <gazebo reference="seg_3_right_upper_leg_link">
    <material>Gazebo/Black</material>
    <selfCollide>True</selfCollide>
    <mu1>1.0</mu1>
    <mu2>1.0</mu2>
    <kp>10000000.0</kp>
    <kd>1.0</kd>
  </gazebo>

  <gazebo reference="seg_3_left_lower_leg_link">
    <material>Gazebo/Orange</material>1000
    <selfCollide>True</selfCollide>
    <mu1>1.0</mu1>
    <mu2>1.0</mu2>
    <kp>10000000.0</kp>
    <kd>1.0</kd>
  </gazebo>

  <gazebo reference="seg_3_right_lower_leg_link">
    <material>Gazebo/Orange</material>
    <selfCollide>True</selfCollide>
    <mu1>1.0</mu1>
    <mu2>1.0</mu2>
    <kp>10000000.0</kp>
    <kd>1.0</kd>
  </gazebo>

  <!-- kp and kd for rubber -->
  <gazebo reference="seg_3_left_foot_link">
    <material>Gazebo/Black</material>
    <mu1>10000.0</mu1>
    <mu2>10000.0</mu2>
    <kp>10000.0</kp>
    <kd>100.0</kd>
    <maxVel>0.5</maxVel>
    <minDepth>0.009</minDepth>
  </gazebo>

  <!-- kp and kd for rubber -->
  <gazebo reference="seg_3_right_foot_link">
    <material>Gazebo/Black</material>
    <mu1>10000.0</mu1>
    <mu2>10000.0</mu2>
    <kp>10000.0</kp>
    <kd>100.0</kd>
    <maxVel>0.5</maxVel>
    <minDepth>0.009</minDepth>
  </gazebo>

  <gazebo reference="seg_3_left_hip_joint">
    <implicitSpringDamper>True</implicitSpringDamper>
  </gazebo>

  <gazebo reference="seg_3_right_hip_joint">
    <implicitSpringDamper>True</implicitSpringDamper>
  </gazebo>

  <gazebo reference="seg_3_left_knee_joint">
    <implicitSpringDamper>True</implicitSpringDamper>
  </gazebo>

  <gazebo reference="seg_3_right_knee_joint">
    <implicitSpringDamper>True</implicitSpringDamper>
  </gazebo>

  <gazebo reference="seg_3_left_foot_joint">
    <implicitSpringDamper>True</implicitSpringDamper>
  </gazebo>

  <gazebo reference="seg_3_right_foot_joint">
    <implicitSpringDamper>True</implicitSpringDamper>
  </gazebo>

  <gazebo>
    <plugin name="boilerplate_motor_plugin"
            filename="libboilerplate_motor_plugin.so">
      <actuatorJoint>seg_3_left_hip_joint</actuatorJoint>
      <maxTorque>40.0</maxTorque>
      <posPidPGain>85.0</posPidPGain>
      <posPidIGain>15.0</posPidIGain>
      <posPidDGain>25.0</posPidDGain>
      <posPidIMax>30.0</posPidIMax>
      <posPidIMin>-30.0</posPidIMin>
      <initialPosition>0.0</initialPosition>
      <cmdPosTopic>seg3_leftleg_to_lefthip</cmdPosTopic>
      <anglePosTopic>seg3_lefthip_to_leftleg</anglePosTopic>
    </plugin>
  </gazebo>

  <gazebo>
    <plugin name="boilerplate_motor_plugin"
            filename="libboilerplate_motor_plugin.so">
      <actuatorJoint>seg_3_right_hip_joint</actuatorJoint>
      <maxTorque>40.0</maxTorque>
      <posPidPGain>85.0</posPidPGain>
      <posPidIGain>15.0</posPidIGain>
      <posPidDGain>25.0</posPidDGain>
      <posPidIMax>30.0</posPidIMax>
      <posPidIMin>-30.0</posPidIMin>
      <initialPosition>0.0</initialPosition>
      <cmdPosTopic>seg3_rightleg_to_righthip</cmdPosTopic>
      <anglePosTopic>seg3_righthip_to_rightleg</anglePosTopic>
    </plugin>
  </gazebo>

  <gazebo>
    <plugin name="boilerplate_motor_plugin"
            filename="libboilerplate_motor_plugin.so">
      <actuatorJoint>seg_3_left_knee_joint</actuatorJoint>
      <maxTorque>40.0</maxTorque>
      <posPidPGain>85.0</posPidPGain>
      <posPidIGain>15.0</posPidIGain>
      <posPidDGain>25.0</posPidDGain>
      <posPidIMax>30.0</posPidIMax>
      <posPidIMin>-30.0</posPidIMin>
      <initialPosition>0.0</initialPosition>
      <cmdPosTopic>seg3_leftleg_to_leftknee</cmdPosTopic>
      <anglePosTopic>seg3_leftknee_to_leftleg</anglePosTopic>
    </plugin>
  </gazebo>

  <gazebo>
    <plugin name="boilerplate_motor_plugin"
            filename="libboilerplate_motor_plugin.so">
      <actuatorJoint>seg_3_right_knee_joint</actuatorJoint>
      <maxTorque>40.0</maxTorque>
      <posPidPGain>85.0</posPidPGain>
      <posPidIGain>15.0</posPidIGain>
      <posPidDGain>25.0</posPidDGain>
      <posPidIMax>30.0</posPidIMax>
      <posPidIMin>-30.0</posPidIMin>
      <initialPosition>0.0</initialPosition>
      <cmdPosTopic>seg3_rightleg_to_rightknee</cmdPosTopic>
      <anglePosTopic>seg3_rightknee_to_rightleg</anglePosTopic>
    </plugin>
  </gazebo>

  <!-- segment 4 -->
  <gazebo reference="seg_4">
    <material>Gazebo/White</material>
    <mu1>1.0</mu1>
    <mu2>1.0</mu2>
    <kp>10000000.0</kp>
    <kd>100.0</kd>
  </gazebo>

  <gazebo reference="seg_4_left_upper_leg_link">
    <material>Gazebo/Black</material>
    <selfCollide>True</selfCollide>
    <mu1>1.0</mu1>
    <mu2>1.0</mu2>
    <kp>10000000.0</kp>
    <kd>1.0</kd>
  </gazebo>

  <gazebo reference="seg_4_right_upper_leg_link">
    <material>Gazebo/Black</material>
    <selfCollide>True</selfCollide>
    <mu1>1.0</mu1>
    <mu2>1.0</mu2>
    <kp>10000000.0</kp>
    <kd>1.0</kd>
  </gazebo>

  <gazebo reference="seg_4_left_lower_leg_link">
    <material>Gazebo/Orange</material>
    <selfCollide>True</selfCollide>
    <mu1>1.0</mu1>
    <mu2>1.0</mu2>
    <kp>10000000.0</kp>
    <kd>1.0</kd>
  </gazebo>

  <gazebo reference="seg_4_right_lower_leg_link">
    <material>Gazebo/Orange</material>
    <selfCollide>True</selfCollide>
    <mu1>1.0</mu1>
    <mu2>1.0</mu2>
    <kp>10000000.0</kp>
    <kd>1.0</kd>
  </gazebo>

  <!-- kp and kd for rubber -->
  <gazebo reference="seg_4_left_foot_link">
    <material>Gazebo/Black</material>
    <mu1>10000.0</mu1>
    <mu2>10000.0</mu2>
    <kp>10000.0</kp>
    <kd>100.0</kd>
    <maxVel>0.9</maxVel>
    <minDepth>0.009</minDepth>
  </gazebo>

  <!-- kp and kd for rubber -->
  <gazebo reference="seg_4_right_foot_link">
    <material>Gazebo/Black</material>
    <mu1>10000.0</mu1>
    <mu2>10000.0</mu2>
    <kp>10000.0</kp>
    <kd>100.0</kd>
    <maxVel>0.9</maxVel>
    <minDepth>0.009</minDepth>
  </gazebo>

  <gazebo reference="seg_4_left_hip_joint">
    <implicitSpringDamper>True</implicitSpringDamper>
  </gazebo>

  <gazebo reference="seg_4_right_hip_joint">
    <implicitSpringDamper>True</implicitSpringDamper>
  </gazebo>

  <gazebo reference="seg_4_left_knee_joint">
    <implicitSpringDamper>True</implicitSpringDamper>
  </gazebo>

  <gazebo reference="seg_4_right_knee_joint">
    <implicitSpringDamper>True</implicitSpringDamper>
  </gazebo>

  <gazebo reference="seg_4_left_foot_joint">
    <implicitSpringDamper>True</implicitSpringDamper>
  </gazebo>

  <gazebo reference="seg_4_right_foot_joint">
    <implicitSpringDamper>True</implicitSpringDamper>
  </gazebo>

  <gazebo>
    <plugin name="boilerplate_motor_plugin"
            filename="libboilerplate_motor_plugin.so">
      <actuatorJoint>seg_4_left_hip_joint</actuatorJoint>
      <maxTorque>40.0</maxTorque>
      <posPidPGain>85.0</posPidPGain>
      <posPidIGain>15.0</posPidIGain>
      <posPidDGain>25.0</posPidDGain>
      <posPidIMax>30.0</posPidIMax>
      <posPidIMin>-30.0</posPidIMin>
      <initialPosition>0.0</initialPosition>
      <cmdPosTopic>seg4_leftleg_to_lefthip</cmdPosTopic>
      <anglePosTopic>seg4_lefthip_to_leftleg</anglePosTopic>
    </plugin>
  </gazebo>

  <gazebo>
    <plugin name="boilerplate_motor_plugin"
            filename="libboilerplate_motor_plugin.so">
      <actuatorJoint>seg_4_right_hip_joint</actuatorJoint>
      <maxTorque>40.0</maxTorque>
      <posPidPGain>85.0</posPidPGain>
      <posPidIGain>15.0</posPidIGain>
      <posPidDGain>25.0</posPidDGain>
      <posPidIMax>30.0</posPidIMax>
      <posPidIMin>-30.0</posPidIMin>
      <initialPosition>0.0</initialPosition>
      <cmdPosTopic>seg4_rightleg_to_righthip</cmdPosTopic>
      <anglePosTopic>seg4_righthip_to_rightleg</anglePosTopic>
    </plugin>
  </gazebo>

  <gazebo>
    <plugin name="boilerplate_motor_plugin"
            filename="libboilerplate_motor_plugin.so">
      <actuatorJoint>seg_4_left_knee_joint</actuatorJoint>
      <maxTorque>40.0</maxTorque>
      <posPidPGain>85.0</posPidPGain>
      <posPidIGain>15.0</posPidIGain>
      <posPidDGain>25.0</posPidDGain>
      <posPidIMax>30.0</posPidIMax>
      <posPidIMin>-30.0</posPidIMin>
      <initialPosition>0.0</initialPosition>
      <cmdPosTopic>seg4_leftleg_to_leftknee</cmdPosTopic>
      <anglePosTopic>seg4_leftknee_to_leftleg</anglePosTopic>
    </plugin>
  </gazebo>

  <gazebo>
    <plugin name="boilerplate_motor_plugin"
            filename="libboilerplate_motor_plugin.so">
      <actuatorJoint>seg_4_right_knee_joint</actuatorJoint>
      <maxTorque>40.0</maxTorque>
      <posPidPGain>85.0</posPidPGain>
      <posPidIGain>15.0</posPidIGain>
      <posPidDGain>25.0</posPidDGain>
      <posPidIMax>30.0</posPidIMax>
      <posPidIMin>-30.0</posPidIMin>
      <initialPosition>0.0</initialPosition>
      <cmdPosTopic>seg4_rightleg_to_rightknee</cmdPosTopic>
      <anglePosTopic>seg4_rightknee_to_rightleg</anglePosTopic>
    </plugin>
  </gazebo>

  <!-- segment 5 -->
  <gazebo reference="seg_5">
    <material>Gazebo/White</material>
    <mu1>1.0</mu1>
    <mu2>1.0</mu2>
    <kp>10000000.0</kp>
    <kd>100.0</kd>
  </gazebo>

  <gazebo reference="seg_5_left_upper_leg_link">
    <material>Gazebo/Black</material>
    <selfCollide>True</selfCollide>
    <mu1>1.0</mu1>
    <mu2>1.0</mu2>
    <kp>10000000.0</kp>
    <kd>1.0</kd>
  </gazebo>

  <gazebo reference="seg_5_right_upper_leg_link">
    <material>Gazebo/Black</material>
    <selfCollide>True</selfCollide>
    <mu1>1.0</mu1>
    <mu2>1.0</mu2>
    <kp>10000000.0</kp>
    <kd>1.0</kd>
  </gazebo>

  <gazebo reference="seg_5_left_lower_leg_link">
    <material>Gazebo/Orange</material>
    <selfCollide>True</selfCollide>
    <mu1>1.0</mu1>
    <mu2>1.0</mu2>
    <kp>10000000.0</kp>
    <kd>1.0</kd>
  </gazebo>

  <gazebo reference="seg_5_right_lower_leg_link">
    <material>Gazebo/Orange</material>
    <selfCollide>True</selfCollide>
    <mu1>1.0</mu1>
    <mu2>1.0</mu2>
    <kp>10000000.0</kp>
    <kd>1.0</kd>
  </gazebo>

  <!-- kp and kd for rubber -->
  <gazebo reference="seg_5_left_foot_link">
    <material>Gazebo/Black</material>
    <mu1>10000.0</mu1>
    <mu2>10000.0</mu2>
    <kp>10000.0</kp>
    <kd>100.0</kd>
    <maxVel>0.5</maxVel>
    <minDepth>0.009</minDepth>
  </gazebo>

  <!-- kp and kd for rubber -->
  <gazebo reference="seg_5_right_foot_link">
    <material>Gazebo/Black</material>
    <mu1>10000.0</mu1>
    <mu2>10000.0</mu2>
    <kp>10000.0</kp>
    <kd>100.0</kd>
    <maxVel>0.5</maxVel>
    <minDepth>0.009</minDepth>
  </gazebo>

  <gazebo reference="seg_5_left_hip_joint">
    <implicitSpringDamper>True</implicitSpringDamper>
  </gazebo>

  <gazebo reference="seg_5_right_hip_joint">
    <implicitSpringDamper>True</implicitSpringDamper>
  </gazebo>

  <gazebo reference="seg_5_left_knee_joint">
    <implicitSpringDamper>True</implicitSpringDamper>
  </gazebo>

  <gazebo reference="seg_5_right_knee_joint">
    <implicitSpringDamper>True</implicitSpringDamper>
  </gazebo>

  <gazebo reference="seg_5_left_foot_joint">
    <implicitSpringDamper>True</implicitSpringDamper>
  </gazebo>

  <gazebo reference="seg_5_right_foot_joint">
    <implicitSpringDamper>True</implicitSpringDamper>
  </gazebo>

  <gazebo>
    <plugin name="boilerplate_motor_plugin"
            filename="libboilerplate_motor_plugin.so">
      <actuatorJoint>seg_5_left_hip_joint</actuatorJoint>
      <maxTorque>40.0</maxTorque>
      <posPidPGain>85.0</posPidPGain>
      <posPidIGain>15.0</posPidIGain>
      <posPidDGain>25.0</posPidDGain>
      <posPidIMax>30.0</posPidIMax>
      <posPidIMin>-30.0</posPidIMin>
      <initialPosition>0.0</initialPosition>
      <cmdPosTopic>seg5_leftleg_to_lefthip</cmdPosTopic>
      <anglePosTopic>seg5_lefthip_to_leftleg</anglePosTopic>
    </plugin>
  </gazebo>

  <gazebo>
    <plugin name="boilerplate_motor_plugin"
            filename="libboilerplate_motor_plugin.so">
      <actuatorJoint>seg_5_right_hip_joint</actuatorJoint>
      <maxTorque>40.0</maxTorque>
      <posPidPGain>85.0</posPidPGain>
      <posPidIGain>15.0</posPidIGain>
      <posPidDGain>25.0</posPidDGain>
      <posPidIMax>30.0</posPidIMax>
      <posPidIMin>-30.0</posPidIMin>
      <initialPosition>0.0</initialPosition>
      <cmdPosTopic>seg5_rightleg_to_righthip</cmdPosTopic>
      <anglePosTopic>seg5_righthip_to_rightleg</anglePosTopic>
    </plugin>
  </gazebo>

  <gazebo>
    <plugin name="boilerplate_motor_plugin"
            filename="libboilerplate_motor_plugin.so">
      <actuatorJoint>seg_5_left_knee_joint</actuatorJoint>
      <maxTorque>40.0</maxTorque>
      <posPidPGain>85.0</posPidPGain>
      <posPidIGain>15.0</posPidIGain>
      <posPidDGain>25.0</posPidDGain>
      <posPidIMax>30.0</posPidIMax>
      <posPidIMin>-30.0</posPidIMin>
      <initialPosition>0.0</initialPosition>
      <cmdPosTopic>seg5_leftleg_to_leftknee</cmdPosTopic>
      <anglePosTopic>seg5_leftknee_to_leftleg</anglePosTopic>
    </plugin>
  </gazebo>

  <gazebo>
    <plugin name="boilerplate_motor_plugin"
            filename="libboilerplate_motor_plugin.so">
      <actuatorJoint>seg_5_right_knee_joint</actuatorJoint>
      <maxTorque>40.0</maxTorque>
      <posPidPGain>85.0</posPidPGain>
      <posPidIGain>15.0</posPidIGain>
      <posPidDGain>25.0</posPidDGain>
      <posPidIMax>30.0</posPidIMax>
      <posPidIMin>-30.0</posPidIMin>
      <initialPosition>0.0</initialPosition>
      <cmdPosTopic>seg5_rightleg_to_rightknee</cmdPosTopic>
      <anglePosTopic>seg5_rightknee_to_rightleg</anglePosTopic>
    </plugin>
  </gazebo>

  <gazebo reference="seg_0_to_connector_0_b">
    <implicitSpringDamper>True</implicitSpringDamper>
  </gazebo>

  <gazebo reference="connector_0_b_to_connector_0">
    <implicitSpringDamper>True</implicitSpringDamper>
  </gazebo>

  <gazebo reference="connector_0_to_seg_1">
    <implicitSpringDamper>True</implicitSpringDamper>
  </gazebo>

  <gazebo reference="seg_1_to_connector_1_b">
    <implicitSpringDamper>True</implicitSpringDamper>
  </gazebo>

  <gazebo reference="connector_1_b_to_connector_1">
    <implicitSpringDamper>True</implicitSpringDamper>
  </gazebo>

  <gazebo reference="connector_1_to_seg_2">
    <implicitSpringDamper>True</implicitSpringDamper>
  </gazebo>

  <gazebo reference="seg_2_to_connector_2_b">
    <implicitSpringDamper>True</implicitSpringDamper>
  </gazebo>

  <gazebo reference="connector_2_b_to_connector_2">
    <implicitSpringDamper>True</implicitSpringDamper>
  </gazebo>

  <gazebo reference="connector_2_to_seg_3">
    <implicitSpringDamper>True</implicitSpringDamper>
  </gazebo>

  <gazebo reference="seg_3_to_connector_3_b">
    <implicitSpringDamper>True</implicitSpringDamper>
  </gazebo>

  <gazebo reference="connector_3_b_to_connector_3">
    <implicitSpringDamper>True</implicitSpringDamper>
  </gazebo>

  <gazebo reference="connector_3_to_seg_4">
    <implicitSpringDamper>True</implicitSpringDamper>
  </gazebo>

  <gazebo reference="seg_4_to_connector_4_b">
    <implicitSpringDamper>True</implicitSpringDamper>
  </gazebo>

  <gazebo reference="connector_4_b_to_connector_4">
    <implicitSpringDamper>True</implicitSpringDamper>
  </gazebo>

  <gazebo reference="connector_4_to_seg_5">
    <implicitSpringDamper>True</implicitSpringDamper>
  </gazebo>

</robot>
